Workbook

Sheet SB1
A1: Codigo | B1: Descripcion | C1: Grupo
A2: 000001 | B2: MERCADERIA SALDOS | C2: 0147
A3: 000002 | B3: CINTA PELIGRO X 100 MTS DOBLE FAZ(CP100) | C3: 0165
A4: 000003 | B4: CINTA PELIGRO X 200 MTS DOBLE FAZ(CP200) | C4: 0165
A5: 000004 | B5: PISTOLA APLICADORA SKELETOR REFORZADA | C5: 0165
A6: 000005 | B6: PORTA PINCEL MAGNETICO | C6: 0165
A7: 000006 | B7: COBERTURA PLASTICA MULTIUSO 3X3MTS.(AC315) | C7: 0165
A8: 000007 | B8: COBERTURA PLASTICA MULTIUSO 3X4MTS.(AC316) | C8: 0165
A9: 000008 | B9: COBERTURA PLASTICA MULTIUSO 3X5MTS.(AC317) | C9: 0165
A10: 000009 | B10: FONDO ANTIOXIDO COLORIN ROJO X 0,250 | C10: 0116
A11: 000010 | B11: ESMALTE SINTETICO TERSUAVE 2EN1 MATE NEGRO X 0,500 | C11: 0152
A12: 000011 | B12: ESMALTE SINTETICO TERSUAVE 2EN1 MATE NEGRO X 1 | C12: 0152
... A7235: RH0013 | B7235: GASTOS VARIOS ÁREA RRHH | C7235: 0901

Sheet SB2
A1: Sucursal | B1: Producto | C1: Deposito | D1: Desc. Prod | E1: Saldo Actual
A2: 010100 | B2: 000001 | C2: 00 | D2: MERCADERIA SALDOS | E2: 0
A3: 010100 | B3: 000002 | C3: 00 | D3: CINTA PELIGRO X 100 MTS DOBLE FAZ(CP100) | E3: 16
A4: 010100 | B4: 000003 | C4: 00 | D4: CINTA PELIGRO X 200 MTS DOBLE FAZ(CP200) | E4: 16
A5: 010100 | B5: 000004 | C5: 00 | D5: PISTOLA APLICADORA SKELETOR REFORZADA | E5: 11
A6: 010100 | B6: 000005 | C6: 00 | D6: PORTA PINCEL MAGNETICO | E6: 0
A7: 010100 | B7: 000006 | C7: 00 | D7: COBERTURA PLASTICA MULTIUSO 3X3MTS.(AC315) | E7: 50
A8: 010100 | B8: 000007 | C8: 00 | D8: COBERTURA PLASTICA MULTIUSO 3X4MTS.(AC316) | E8: 44
A9: 010100 | B9: 000008 | C9: 00 | D9: COBERTURA PLASTICA MULTIUSO 3X5MTS.(AC317) | E9: 56
A10: 010100 | B10: 000009 | C10: 00 | D10: FONDO ANTIOXIDO COLORIN ROJO X 0,250 | E10: 0
A11: 010100 | B11: 000010 | C11: 00 | D11: ESMALTE SINTETICO TERSUAVE 2EN1 MATE NEGRO X 0,500 | E11: 0
A12: 010100 | B12: 000011 | C12: 00 | D12: ESMALTE SINTETICO TERSUAVE 2EN1 MATE NEGRO X 1 | E12: 34
A13: 010100 | B13: 000012 | C13: 00 | D13: ESMALTE SINTETICO TERSUAVE 2EN1 MATE NEGRO X 4 | E13: 12
... A4353: 010100 | B4353: 004944 | C4353: 00 | D4353: RECUBRIMIENTO ATERMIK REFLECTIVO PLAVICON BLANCO X 10 | E4353: 0
A4354: 010100 | B4354: 004945 | C4354: 00 | E4354: 1
A4355: 010100 | B4355: 004949 | C4355: 00 | D4355: REVESTIMIENTO PLASTICO CONTINUO BASE COAT X 27 | E4355: 0
A4356: 010100 | B4356: 004950 | C4356: 00 | D4356: RELLENO FONDO DE JUNTA WEBER 8MM X 1500 MTS. | E4356: 0
A4357: 010100 | B4357: 004951 | C4357: 00 | D4357: RELLENO FONDO DE JUNTA WEBER 15MM X 550MTS. | E4357: 0
A4358: 010100 | B4358: 004952 | C4358: 00 | D4358: RELLENO FONDO DE JUNTA WEBER 25MM X 200 MTS. | E4358: 1
A4359: 010100 | B4359: 004953 | C4359: 00 | D4359: PINTURA PARA PILETA PLAVICON AL AGUA MATE AZUL CARIBE X 1 | E4359: 46
A4360: 010100 | B4360: 004954 | C4360: 00 | D4360: PINTURA PARA PILETA PLAVICON AL AGUA MATE AZUL CARIBE X 4 | E4360: 34
A4361: 010100 | B4361: 004955 | C4361: 00 | D4361: PINTURA PARA PILETA PLAVICON AL AGUA MATE AZUL CARIBE X 10 | E4361: 6
A4362: 010100 | B4362: 004956 | C4362: 00 | D4362: PINTURA PARA PILETA PLAVICON AL AGUA MATE AZUL CARIBE X 20 | E4362: 3
A4363: 010100 | B4363: 004957 | C4363: 00 | D4363: PINTURA PARA PILETA PLAVICON AL AGUA MATE BLANCO X 1 | E4363: 61
A4364: 010100 | B4364: 004958 | C4364: 00 | D4364: PINTURA PARA PILETA PLAVICON AL AGUA MATE BLANCO X 4 | E4364: 47
A4365: 010100 | B4365: 004959 | C4365: 00 | D4365: PINTURA PARA PILETA PLAVICON AL AGUA MATE BLANCO X 10 | E4365: 5
A4366: 010100 | B4366: 004960 | C4366: 00 | D4366: PINTURA PARA PILETA PLAVICON AL AGUA MATE BLANCO X 20 | E4366: 2
... A4378: 010100 | B4378: 004972 | C4378: 00 | D4378: PINTURA PARA PILETA PLAVICON AL AGUA MATE VERDE ESMERALDA X 20 | E4378: 1
A4379: 010100 | B4379: 004985 | C4379: 00 | E4379: 0
A4380: 010100 | B4380: 004986 | C4380: 00 | E4380: 0
A4381: 010100 | B4381: 004987 | C4381: 00 | E4381: 0
A4382: 010100 | B4382: 004988 | C4382: 00 | E4382: 0
A4383: 010100 | B4383: 004989 | C4383: 00 | E4383: 0
A4384: 010100 | B4384: 004994 | C4384: 00 | D4384: PEGAMENTO RAPIDO WEBER PISO SOBRE PISO 12 HS. GRIS X 25 | E4384: 0
A4385: 010100 | B4385: 004995 | C4385: 00 | D4385: PEGAMENTO FLEX.PIEZAS H.60X120 WEBER FLEX PORCELLANATO GRIS X 25 | E4385: 375
A4386: 010100 | B4386: 004996 | C4386: 00 | D4386: ACTIVADOR EPOXY HP 5300 BASE AGUA RUST OLEUM X 0,47 (5301604) | E4386: 5
A4387: 010100 | B4387: 004997 | C4387: 00 | D4387: EPOXY BASE AGUA HP 5300 RUST OLEUM BLANCO X 3,78 (5392408) | E4387: 14
A4388: 010100 | B4388: 004998 | C4388: 00 | D4388: IMPERMEABILIZANTE PARA TECHOS ALBAFRENT SATINADO BLANCO X 4 | E4388: 90
A4389: 010100 | B4389: 004999 | C4389: 00 | D4389: IMPERMEABILIZANTE PARA TECHOS ALBAFRENT SATINADO BLANCO X 10 | E4389: 76
A4390: 010100 | B4390: 005000 | C4390: 00 | D4390: IMPERMEABILIZANTE PARA TECHOS ALBAFRENT SATINADO BLANCO X 20 | E4390: 184
...

Sheet SBM
A1: Cod. Grupo | B1: Desc. Grupo
A2: 0101 | B2: 3D ARGENTINA
A3: 0102 | B3: ABRASIVOS ARGENTINOS
A4: 0103 | B4: ACCESORIOS VARIOS
A5: 0104 | B5: ADIABATIC
A6: 0105 | B6: AKZO NOBEL - CETOL
A7: 0106 | B7: AKZO NOBEL - BRIKOL
A8: 0107 | B8: ALBA HOGAR
A9: 0108 | B9: ALBA TINTING
A10: 0109 | B10: ALBA GLIDDEN
A11: 0110 | B11: ALBA INDUSTRIA
A12: 0111 | B12: INTERNATIONAL
... A106: 0906 | B106: OBSOLETOS

Sheet BD
A1: Producto | B1: Desc. Prod | C1: Saldo Actual | D1: Desc. Grupo | E1: CodeBar
A2: 000001 | B2: =VLOOKUP(A2, 'SB1'!A:B, 2, FALSE) -> MERCADERIA SALDOS | C2: =VLOOKUP(A2, 'SB2'!B:E, 4, FALSE) -> 0 | D2: =VLOOKUP(VLOOKUP(A2, 'SB1'!A:C, 3, FALSE), SBM!A:B, 2, FALSE) -> SALDOS | E2: =VLOOKUP(A2, CodeBar!A:C, 3, FALSE)
A3: 000002 | B3: =VLOOKUP(A3, 'SB1'!A:B, 2, FALSE) -> CINTA PELIGRO X 100 MTS DOBLE FAZ(CP100) | C3: =VLOOKUP(A3, 'SB2'!B:E, 4, FALSE) -> 16 | D3: =VLOOKUP(VLOOKUP(A3, 'SB1'!A:C, 3, FALSE), SBM!A:B, 2, FALSE) -> MATEZZ | E3: =VLOOKUP(A3, CodeBar!A:C, 3, FALSE) -> 000002
A4: 000003 | B4: =VLOOKUP(A4, 'SB1'!A:B, 2, FALSE) -> CINTA PELIGRO X 200 MTS DOBLE FAZ(CP200) | C4: =VLOOKUP(A4, 'SB2'!B:E, 4, FALSE) -> 16 | D4: =VLOOKUP(VLOOKUP(A4, 'SB1'!A:C, 3, FALSE), SBM!A:B, 2, FALSE) -> MATEZZ | E4: =VLOOKUP(A4, CodeBar!A:C, 3, FALSE) -> 000003
A5: 000004 | B5: =VLOOKUP(A5, 'SB1'!A:B, 2, FALSE) -> PISTOLA APLICADORA SKELETOR REFORZADA | C5: =VLOOKUP(A5, 'SB2'!B:E, 4, FALSE) -> 11 | D5: =VLOOKUP(VLOOKUP(A5, 'SB1'!A:C, 3, FALSE), SBM!A:B, 2, FALSE) -> MATEZZ | E5: =VLOOKUP(A5, CodeBar!A:C, 3, FALSE) -> 756058744679
A6: 000005 | B6: =VLOOKUP(A6, 'SB1'!A:B, 2, FALSE) -> PORTA PINCEL MAGNETICO | C6: =VLOOKUP(A6, 'SB2'!B:E, 4, FALSE) -> 0 | D6: =VLOOKUP(VLOOKUP(A6, 'SB1'!A:C, 3, FALSE), SBM!A:B, 2, FALSE) -> MATEZZ | E6: =VLOOKUP(A6, CodeBar!A:C, 3, FALSE)
A7: 000006 | B7: =VLOOKUP(A7, 'SB1'!A:B, 2, FALSE) -> COBERTURA PLASTICA MULTIUSO 3X3MTS.(AC315) | C7: =VLOOKUP(A7, 'SB2'!B:E, 4, FALSE) -> 50 | D7: =VLOOKUP(VLOOKUP(A7, 'SB1'!A:C, 3, FALSE), SBM!A:B, 2, FALSE) -> MATEZZ | E7: =VLOOKUP(A7, CodeBar!A:C, 3, FALSE) -> 614143485435
A8: 000007 | B8: =VLOOKUP(A8, 'SB1'!A:B, 2, FALSE) -> COBERTURA PLASTICA MULTIUSO 3X4MTS.(AC316) | C8: =VLOOKUP(A8, 'SB2'!B:E, 4, FALSE) -> 44 | D8: =VLOOKUP(VLOOKUP(A8, 'SB1'!A:C, 3, FALSE), SBM!A:B, 2, FALSE) -> MATEZZ | E8: =VLOOKUP(A8, CodeBar!A:C, 3, FALSE) -> 614143485442
A9: 000008 | B9: =VLOOKUP(A9, 'SB1'!A:B, 2, FALSE) -> COBERTURA PLASTICA MULTIUSO 3X5MTS.(AC317) | C9: =VLOOKUP(A9, 'SB2'!B:E, 4, FALSE) -> 56 | D9: =VLOOKUP(VLOOKUP(A9, 'SB1'!A:C, 3, FALSE), SBM!A:B, 2, FALSE) -> MATEZZ | E9: =VLOOKUP(A9, CodeBar!A:C, 3, FALSE) -> 614143485459
A10: 000009 | B10: =VLOOKUP(A10, 'SB1'!A:B, 2, FALSE) -> FONDO ANTIOXIDO COLORIN ROJO X 0,250 | C10: =VLOOKUP(A10, 'SB2'!B:E, 4, FALSE) -> 0 | D10: =VLOOKUP(VLOOKUP(A10, 'SB1'!A:C, 3, FALSE), SBM!A:B, 2, FALSE) -> COLORIN | E10: =VLOOKUP(A10, CodeBar!A:C, 3, FALSE)
A11: 000010 | B11: =VLOOKUP(A11, 'SB1'!A:B, 2, FALSE) -> ESMALTE SINTETICO TERSUAVE 2EN1 MATE NEGRO X 0,500 | C11: =VLOOKUP(A11, 'SB2'!B:E, 4, FALSE) -> 0 | D11: =VLOOKUP(VLOOKUP(A11, 'SB1'!A:C, 3, FALSE), SBM!A:B, 2, FALSE) -> TERSUAVE | E11: =VLOOKUP(A11, CodeBar!A:C, 3, FALSE) -> 7798018382371
A12: 000011 | B12: =VLOOKUP(A12, 'SB1'!A:B, 2, FALSE) -> ESMALTE SINTETICO TERSUAVE 2EN1 MATE NEGRO X 1 | C12: =VLOOKUP(A12, 'SB2'!B:E, 4, FALSE) -> 34 | D12: =VLOOKUP(VLOOKUP(A12, 'SB1'!A:C, 3, FALSE), SBM!A:B, 2, FALSE) -> TERSUAVE | E12: =VLOOKUP(A12, CodeBar!A:C, 3, FALSE) -> 7798018382388
A13: 000012 | B13: =VLOOKUP(A13, 'SB1'!A:B, 2, FALSE) -> ESMALTE SINTETICO TERSUAVE 2EN1 MATE NEGRO X 4 | C13: =VLOOKUP(A13, 'SB2'!B:E, 4, FALSE) -> 12 | D13: =VLOOKUP(VLOOKUP(A13, 'SB1'!A:C, 3, FALSE), SBM!A:B, 2, FALSE) -> TERSUAVE | E13: =VLOOKUP(A13, CodeBar!A:C, 3, FALSE) -> 7798018382395
... A6426: 009641 | B6426: =VLOOKUP(A6426, 'SB1'!A:B, 2, FALSE) -> ESMALTE SINTETICO MAGIC 3EN1 BRILLANTE MARFIL X 4 | C6426: =VLOOKUP(A6426, 'SB2'!B:E, 4, FALSE) -> 0 | D6426: =VLOOKUP(VLOOKUP(A6426, 'SB1'!A:C, 3, FALSE), SBM!A:B, 2, FALSE) -> COLORIN | E6426: =VLOOKUP(A6426, CodeBar!A:C, 3, FALSE)
A6427: 009647 | B6427: =VLOOKUP(A6427, 'SB1'!A:B, 2, FALSE) -> ESMALTE SINTETICO MAGIC 3EN1 MATE BLANCO X 4 | D6427: =VLOOKUP(VLOOKUP(A6427, 'SB1'!A:C, 3, FALSE), SBM!A:B, 2, FALSE) -> COLORIN | E6427: =VLOOKUP(A6427, CodeBar!A:C, 3, FALSE)
A6428: 009649 | B6428: =VLOOKUP(A6428, 'SB1'!A:B, 2, FALSE) -> ESMALTE SINTETICO MAGIC 3EN1 BRILLANTE MARRON/CASTANO X 4 | D6428: =VLOOKUP(VLOOKUP(A6428, 'SB1'!A:C, 3, FALSE), SBM!A:B, 2, FALSE) -> COLORIN | E6428: =VLOOKUP(A6428, CodeBar!A:C, 3, FALSE)
A6429: 009650 | B6429: =VLOOKUP(A6429, 'SB1'!A:B, 2, FALSE) -> ESMALTE SINTETICO MAGIC 3EN1 BRILLANTE AZUL BANDERA X 4 | D6429: =VLOOKUP(VLOOKUP(A6429, 'SB1'!A:C, 3, FALSE), SBM!A:B, 2, FALSE) -> COLORIN | E6429: =VLOOKUP(A6429, CodeBar!A:C, 3, FALSE)
A6430: 009653 | B6430: =VLOOKUP(A6430, 'SB1'!A:B, 2, FALSE) -> ESMALTE SINTETICO MAGIC 3EN1 BRILLANTE TOSTADO X 4 | D6430: =VLOOKUP(VLOOKUP(A6430, 'SB1'!A:C, 3, FALSE), SBM!A:B, 2, FALSE) -> COLORIN | E6430: =VLOOKUP(A6430, CodeBar!A:C, 3, FALSE)
A6431: 009659 | B6431: =VLOOKUP(A6431, 'SB1'!A:B, 2, FALSE) -> ESMALTE SINTETICO MAGIC 3EN1 BRILLANTE OCEANICO X 4 | D6431: =VLOOKUP(VLOOKUP(A6431, 'SB1'!A:C, 3, FALSE), SBM!A:B, 2, FALSE) -> COLORIN | E6431: =VLOOKUP(A6431, CodeBar!A:C, 3, FALSE)
A6432: 009663 | B6432: =VLOOKUP(A6432, 'SB1'!A:B, 2, FALSE) -> ESMALTE SINTETICO MAGIC 3EN1 BRILLANTE AMARILLO X 4 | D6432: =VLOOKUP(VLOOKUP(A6432, 'SB1'!A:C, 3, FALSE), SBM!A:B, 2, FALSE) -> COLORIN | E6432: =VLOOKUP(A6432, CodeBar!A:C, 3, FALSE)
A6433: 009666 | B6433: =VLOOKUP(A6433, 'SB1'!A:B, 2, FALSE) -> ESMALTE SINTETICO MAGIC 3EN1 BRILLANTE CAFE X 4 | D6433: =VLOOKUP(VLOOKUP(A6433, 'SB1'!A:C, 3, FALSE), SBM!A:B, 2, FALSE) -> COLORIN | E6433: =VLOOKUP(A6433, CodeBar!A:C, 3, FALSE)
A6434: 009671 | B6434: =VLOOKUP(A6434, 'SB1'!A:B, 2, FALSE) -> ESMALTE SINTETICO MAGIC 3EN1 MATE NEGRO X 4 | D6434: =VLOOKUP(VLOOKUP(A6434, 'SB1'!A:C, 3, FALSE), SBM!A:B, 2, FALSE) -> COLORIN | E6434: =VLOOKUP(A6434, CodeBar!A:C, 3, FALSE)
A6435: 009701 | B6435: =VLOOKUP(A6435, 'SB1'!A:B, 2, FALSE) -> ESMALTE AL AGUA ALBALUX BRILLANTE BLANCO X 1 | D6435: =VLOOKUP(VLOOKUP(A6435, 'SB1'!A:C, 3, FALSE), SBM!A:B, 2, FALSE) -> ALBA HOGAR | E6435: =VLOOKUP(A6435, CodeBar!A:C, 3, FALSE) -> 7796374850268
A6436: 009702 | B6436: =VLOOKUP(A6436, 'SB1'!A:B, 2, FALSE) -> ESM.AGUA ALBA ROJO DERBY X 1 | D6436: =VLOOKUP(VLOOKUP(A6436, 'SB1'!A:C, 3, FALSE), SBM!A:B, 2, FALSE) -> PRODUCTOS DISCONTINUADOS | E6436: =VLOOKUP(A6436, CodeBar!A:C, 3, FALSE)
A6437: 009704 | B6437: =VLOOKUP(A6437, 'SB1'!A:B, 2, FALSE) -> ESM.AGUA ALBA AMAR.DAISY X 1 | D6437: =VLOOKUP(VLOOKUP(A6437, 'SB1'!A:C, 3, FALSE), SBM!A:B, 2, FALSE) -> PRODUCTOS DISCONTINUADOS | E6437: =VLOOKUP(A6437, CodeBar!A:C, 3, FALSE)
A6438: 009715 | B6438: =VLOOKUP(A6438, 'SB1'!A:B, 2, FALSE) -> ESMALTE AL AGUA ALBALUX BRILLANTE NEGRO X 1 | D6438: =VLOOKUP(VLOOKUP(A6438, 'SB1'!A:C, 3, FALSE), SBM!A:B, 2, FALSE) -> ALBA HOGAR | E6438: =VLOOKUP(A6438, CodeBar!A:C, 3, FALSE) -> 7796374850350
... A7235: RH0013 | B7235: =VLOOKUP(A7235, 'SB1'!A:B, 2, FALSE) -> GASTOS VARIOS ÁREA RRHH | D7235: =VLOOKUP(VLOOKUP(A7235, 'SB1'!A:C, 3, FALSE), SBM!A:B, 2, FALSE) -> RECURSOS HUMANOS | E7235: =VLOOKUP(A7235, CodeBar!A:C, 3, FALSE)

Sheet CodeBar
A1: Codigo | B1: Descripcion | C1: Cod. Barras
A2: 000001 | B2: MERCADERIA SALDOS
A3: 000002 | B3: CINTA PELIGRO X 100 MTS DOBLE FAZ(CP100) | C3: 000002
A4: 000003 | B4: CINTA PELIGRO X 200 MTS DOBLE FAZ(CP200) | C4: 000003
A5: 000004 | B5: PISTOLA APLICADORA SKELETOR REFORZADA | C5: 756058744679
A6: 000005 | B6: PORTA PINCEL MAGNETICO
A7: 000006 | B7: COBERTURA PLASTICA MULTIUSO 3X3MTS.(AC315) | C7: 614143485435
A8: 000007 | B8: COBERTURA PLASTICA MULTIUSO 3X4MTS.(AC316) | C8: 614143485442
A9: 000008 | B9: COBERTURA PLASTICA MULTIUSO 3X5MTS.(AC317) | C9: 614143485459
A10: 000009 | B10: FONDO ANTIOXIDO COLORIN ROJO X 0,250
A11: 000010 | B11: ESMALTE SINTETICO TERSUAVE 2EN1 MATE NEGRO X 0,500 | C11: 7798018382371
A12: 000011 | B12: ESMALTE SINTETICO TERSUAVE 2EN1 MATE NEGRO X 1 | C12: 7798018382388
A13: 000012 | B13: ESMALTE SINTETICO TERSUAVE 2EN1 MATE NEGRO X 4 | C13: 7798018382395
A14: 000013 | B14: ESMALTE SINTETICO TERSUAVE 2EN1 MATE BLANCO X 0,500 | C14: 7798018382326
A15: 000014 | B15: ESMALTE SINTETICO TERSUAVE 2EN1 MATE BLANCO X 1 | C15: 7798018382333
A16: 000015 | B16: ESMALTE SINTETICO TERSUAVE 2EN1 MATE BLANCO X 4 | C16: 7798018382340
A17: 000016 | B17: FONDO ANTIOXIDO COLORIN ROJO X 0,500
A18: 000017 | B18: FONDO ANTIOXIDO COLORIN ROJO X 1
A19: 000018 | B19: FONDO ANTIOXIDO COLORIN ROJO X 4
A20: 000019 | B20: FONDO ANTIOXIDO COLORIN ROJO X 20
A21: 000020 | B21: FONDO PARA MADERA COLORIN BLANCO X 0,500
A22: 000021 | B22: FONDO PARA MADERA COLORIN BLANCO X 1
A23: 000022 | B23: FONDO PARA MADERA COLORIN BLANCO X 4
A24: 000023 | B24: FONDO PARA MADERA COLORIN BLANCO X 20
A25: 000024 | B25: AUTOPOLISH COLORIN AUTOCERA X 0,450 | C25: 7790715013138
A26: 000025 | B26: AUTOPOLISH COLORIN BICAPA X 0,450 | C26: 7790715013152
A27: 000026 | B27: BARNIZ PARA MADERA EXTERIOR ALBATROS AL AGUA BRILLANTE INCOLORO X 1
A28: 000027 | B28: BARNIZ PARA MADERA EXTERIOR ALBATROS AL AGUA BRILLANTE INCOLORO X 4 | C28: 7796374008447
A29: 000028 | B29: REMOVEDOR GEL PETRILAC X 4
A30: 000029 | B30: LATEX INTERIOR COLORIN ACRYLATEX MATE BLANCO X 1
A31: 000030 | B31: LATEX INTERIOR COLORIN ACRYLATEX MATE BLANCO X 4
A32: 000031 | B32: LATEX INTERIOR COLORIN ACRYLATEX MATE BLANCO X 20
A33: 000032 | B33: LATEX PARA CIELORRASOS COLORIN MATE BLANCO X 1
A34: 000033 | B34: LATEX PARA CIELORRASOS COLORIN MATE BLANCO X 4
A35: 000034 | B35: LATEX PARA CIELORRASOS COLORIN MATE BLANCO X 20
A36: 000035 | B36: ENDUIDO INTERIOR COLORIN SUPER LIVIANO X 10
A37: 000036 | B37: ENDUIDO INTERIOR COLORIN SUPER LIVIANO X 1
A38: 000037 | B38: ENDUIDO INTERIOR COLORIN SUPER LIVIANO X 4
A39: 000038 | B39: ENDUIDO EXTERIOR COLORIN X 1
A40: 000039 | B40: ENDUIDO EXTERIOR COLORIN X 4
...
